Traceback (most recent call last):
  File "/Users/evanmuzzall/opt/anaconda3/lib/python3.8/site-packages/nbclient/client.py", line 730, in _async_poll_for_reply
    msg = await ensure_async(self.kc.shell_channel.get_msg(timeout=new_timeout))
  File "/Users/evanmuzzall/opt/anaconda3/lib/python3.8/site-packages/nbclient/util.py", line 96, in ensure_async
    result = await obj
  File "/Users/evanmuzzall/opt/anaconda3/lib/python3.8/site-packages/jupyter_client/asynchronous/channels.py", line 48, in get_msg
    raise Empty
_queue.Empty

During handling of the above exception, another exception occurred:

Traceback (most recent call last):
  File "/Users/evanmuzzall/opt/anaconda3/lib/python3.8/site-packages/jupyter_cache/executors/utils.py", line 51, in single_nb_execution
    executenb(
  File "/Users/evanmuzzall/opt/anaconda3/lib/python3.8/site-packages/nbclient/client.py", line 1204, in execute
    return NotebookClient(nb=nb, resources=resources, km=km, **kwargs).execute()
  File "/Users/evanmuzzall/opt/anaconda3/lib/python3.8/site-packages/nbclient/util.py", line 84, in wrapped
    return just_run(coro(*args, **kwargs))
  File "/Users/evanmuzzall/opt/anaconda3/lib/python3.8/site-packages/nbclient/util.py", line 62, in just_run
    return loop.run_until_complete(coro)
  File "/Users/evanmuzzall/opt/anaconda3/lib/python3.8/asyncio/base_events.py", line 616, in run_until_complete
    return future.result()
  File "/Users/evanmuzzall/opt/anaconda3/lib/python3.8/site-packages/nbclient/client.py", line 663, in async_execute
    await self.async_execute_cell(
  File "/Users/evanmuzzall/opt/anaconda3/lib/python3.8/site-packages/nbclient/client.py", line 949, in async_execute_cell
    exec_reply = await self.task_poll_for_reply
  File "/Users/evanmuzzall/opt/anaconda3/lib/python3.8/site-packages/nbclient/client.py", line 754, in _async_poll_for_reply
    await self._async_handle_timeout(timeout, cell)
  File "/Users/evanmuzzall/opt/anaconda3/lib/python3.8/site-packages/nbclient/client.py", line 801, in _async_handle_timeout
    raise CellTimeoutError.error_from_timeout_and_cell(
nbclient.exceptions.CellTimeoutError: A cell timed out while it was being executed, after 30 seconds.
The message was: Cell execution timed out.
Here is a preview of the cell contents:
-------------------
['# Cross-validated model!', "text_clf = Pipeline([('vect', CountVectorizer(ngram_range=(1, 3))),", "                    ('tfidf', TfidfTransformer()),", "                    ('clf', LogisticRegression(solver = 'liblinear',", "                                               penalty = 'l2', "]
...
['# for your own research, thesis, or publication', '# you would select cv equal to 10 or 20', 'scores = cross_val_score(text_clf, x, y, cv = 10)', '', 'print(scores, np.mean(scores))']
-------------------

