Traceback (most recent call last):
  File "/Users/evanmuzzall/opt/anaconda3/lib/python3.8/site-packages/jupyter_cache/executors/utils.py", line 51, in single_nb_execution
    executenb(
  File "/Users/evanmuzzall/opt/anaconda3/lib/python3.8/site-packages/nbclient/client.py", line 1204, in execute
    return NotebookClient(nb=nb, resources=resources, km=km, **kwargs).execute()
  File "/Users/evanmuzzall/opt/anaconda3/lib/python3.8/site-packages/nbclient/util.py", line 84, in wrapped
    return just_run(coro(*args, **kwargs))
  File "/Users/evanmuzzall/opt/anaconda3/lib/python3.8/site-packages/nbclient/util.py", line 62, in just_run
    return loop.run_until_complete(coro)
  File "/Users/evanmuzzall/opt/anaconda3/lib/python3.8/asyncio/base_events.py", line 616, in run_until_complete
    return future.result()
  File "/Users/evanmuzzall/opt/anaconda3/lib/python3.8/site-packages/nbclient/client.py", line 663, in async_execute
    await self.async_execute_cell(
  File "/Users/evanmuzzall/opt/anaconda3/lib/python3.8/site-packages/nbclient/client.py", line 965, in async_execute_cell
    await self._check_raise_for_error(cell, cell_index, exec_reply)
  File "/Users/evanmuzzall/opt/anaconda3/lib/python3.8/site-packages/nbclient/client.py", line 862, in _check_raise_for_error
    raise CellExecutionError.from_cell_and_msg(cell, exec_reply_content)
nbclient.exceptions.CellExecutionError: An error occurred while executing the following cell:
------------------
from pycontractions import Contractions as ct

# load contractions from a vector model - many models accepted!
contractions = ct('GoogleNews-vectors-negative300.bin')

# optional: load the model before the first .expand_texts call 
ct.load_models() 

example_sentence = "I'd like to know how you're doing! You're her best friend, but I'm your friend too, aren't I?"

# let's see the text, de-contraction-afied!
print(list(ct.expand_texts([example_sentence])))
------------------

[0;31m---------------------------------------------------------------------------[0m
[0;31mModuleNotFoundError[0m                       Traceback (most recent call last)
[0;32m/var/folders/9g/fhnd1v790cj5ccxlv4rcvsy40000gq/T/ipykernel_32685/1793476377.py[0m in [0;36m<module>[0;34m[0m
[0;32m----> 1[0;31m [0;32mfrom[0m [0mpycontractions[0m [0;32mimport[0m [0mContractions[0m [0;32mas[0m [0mct[0m[0;34m[0m[0;34m[0m[0m
[0m[1;32m      2[0m [0;34m[0m[0m
[1;32m      3[0m [0;31m# load contractions from a vector model - many models accepted![0m[0;34m[0m[0;34m[0m[0;34m[0m[0m
[1;32m      4[0m [0mcontractions[0m [0;34m=[0m [0mct[0m[0;34m([0m[0;34m'GoogleNews-vectors-negative300.bin'[0m[0;34m)[0m[0;34m[0m[0;34m[0m[0m
[1;32m      5[0m [0;34m[0m[0m

[0;31mModuleNotFoundError[0m: No module named 'pycontractions'
ModuleNotFoundError: No module named 'pycontractions'

