Traceback (most recent call last):
  File "/Users/evanmuzzall/opt/anaconda3/lib/python3.8/site-packages/jupyter_cache/executors/utils.py", line 51, in single_nb_execution
    executenb(
  File "/Users/evanmuzzall/opt/anaconda3/lib/python3.8/site-packages/nbclient/client.py", line 1204, in execute
    return NotebookClient(nb=nb, resources=resources, km=km, **kwargs).execute()
  File "/Users/evanmuzzall/opt/anaconda3/lib/python3.8/site-packages/nbclient/util.py", line 84, in wrapped
    return just_run(coro(*args, **kwargs))
  File "/Users/evanmuzzall/opt/anaconda3/lib/python3.8/site-packages/nbclient/util.py", line 62, in just_run
    return loop.run_until_complete(coro)
  File "/Users/evanmuzzall/opt/anaconda3/lib/python3.8/asyncio/base_events.py", line 616, in run_until_complete
    return future.result()
  File "/Users/evanmuzzall/opt/anaconda3/lib/python3.8/site-packages/nbclient/client.py", line 663, in async_execute
    await self.async_execute_cell(
  File "/Users/evanmuzzall/opt/anaconda3/lib/python3.8/site-packages/nbclient/client.py", line 965, in async_execute_cell
    await self._check_raise_for_error(cell, cell_index, exec_reply)
  File "/Users/evanmuzzall/opt/anaconda3/lib/python3.8/site-packages/nbclient/client.py", line 862, in _check_raise_for_error
    raise CellExecutionError.from_cell_and_msg(cell, exec_reply_content)
nbclient.exceptions.CellExecutionError: An error occurred while executing the following cell:
------------------
# generate toy dataset
example = {'x1': [1, 0, 1, 1, 0], 
           'x2': [1, 1, 1, 1, 0], 
           'xm': [1, 0, 1, 1, 0],
           'y': ['yes', 'no', 'yes', 'yes', 'no']
           }
example_df = pd.DataFrame(data = example)
example_df
------------------

[0;31m---------------------------------------------------------------------------[0m
[0;31mNameError[0m                                 Traceback (most recent call last)
[0;32m/var/folders/9g/fhnd1v790cj5ccxlv4rcvsy40000gq/T/ipykernel_59292/2635824310.py[0m in [0;36m<module>[0;34m[0m
[1;32m      5[0m            [0;34m'y'[0m[0;34m:[0m [0;34m[[0m[0;34m'yes'[0m[0;34m,[0m [0;34m'no'[0m[0;34m,[0m [0;34m'yes'[0m[0;34m,[0m [0;34m'yes'[0m[0;34m,[0m [0;34m'no'[0m[0;34m][0m[0;34m[0m[0;34m[0m[0m
[1;32m      6[0m            }
[0;32m----> 7[0;31m [0mexample_df[0m [0;34m=[0m [0mpd[0m[0;34m.[0m[0mDataFrame[0m[0;34m([0m[0mdata[0m [0;34m=[0m [0mexample[0m[0;34m)[0m[0;34m[0m[0;34m[0m[0m
[0m[1;32m      8[0m [0mexample_df[0m[0;34m[0m[0;34m[0m[0m

[0;31mNameError[0m: name 'pd' is not defined
NameError: name 'pd' is not defined

